<sdf version='1.10'>
  <world name='demo'>
    <plugin name='gz::sim::systems::Physics' filename='gz-sim-physics-system'/>
    <plugin name='gz::sim::systems::Sensors' filename='gz-sim-sensors-system'>
      <render_engine>ogre2</render_engine>
    </plugin>
    <plugin name='gz::sim::systems::SceneBroadcaster' filename='gz-sim-scene-broadcaster-system'/>
    <plugin name='gz::sim::systems::UserCommands' filename='gz-sim-user-commands-system'/>
    <plugin name='ros_gz_example_gazebo::BasicSystem' filename='BasicSystem'/>
    <plugin name='ros_gz_example_gazebo::FullSystem' filename='FullSystem'/>
    <plugin name='gz::sim::systems::TriggeredPublisher' filename='gz-sim-triggered-publisher-system'>
      <input type='gz.msgs.Int32' topic='/keyboard/keypress'>
        <match field='data'>16777234</match>
      </input>
      <output type='gz.msgs.Twist' topic='/model/x3/cmd_vel'>linear: {y: 1.0}</output>
    </plugin>
    <plugin name='gz::sim::systems::TriggeredPublisher' filename='gz-sim-triggered-publisher-system'>
      <input type='gz.msgs.Int32' topic='/keyboard/keypress'>
        <match field='data'>16777235</match>
      </input>
      <output type='gz.msgs.Twist' topic='/model/x3/cmd_vel'>linear: {x: 1.0}</output>
    </plugin>
    <plugin name='gz::sim::systems::TriggeredPublisher' filename='gz-sim-triggered-publisher-system'>
      <input type='gz.msgs.Int32' topic='/keyboard/keypress'>
        <match field='data'>16777236</match>
      </input>
      <output type='gz.msgs.Twist' topic='/model/x3/cmd_vel'>linear: {y: -1.0}</output>
    </plugin>
    <plugin name='gz::sim::systems::TriggeredPublisher' filename='gz-sim-triggered-publisher-system'>
      <input type='gz.msgs.Int32' topic='/keyboard/keypress'>
        <match field='data'>16777237</match>
      </input>
      <output type='gz.msgs.Twist' topic='/model/x3/cmd_vel'>linear: {x: -1.0}</output>
    </plugin>
    <paused>false</paused>
    <gravity>0 0 -9.8000000000000007</gravity>
    <magnetic_field>5.5644999999999998e-06 2.2875799999999999e-05 -4.2388400000000002e-05</magnetic_field>
    <atmosphere type='adiabatic'/>
    <physics type='ode'>
      <max_step_size>0.001</max_step_size>
      <real_time_factor>1</real_time_factor>
      <real_time_update_rate>1000</real_time_update_rate>
    </physics>
    <scene>
      <ambient>0.400000006 0.400000006 0.400000006 1</ambient>
      <background>0.699999988 0.699999988 0.699999988 1</background>
      <shadows>true</shadows>
    </scene>
    <model name='ground_plane'>
      <static>true</static>
      <link name='link'>
        <collision name='collision'>
          <geometry>
            <plane>
              <normal>0 0 1</normal>
              <size>100 100</size>
            </plane>
          </geometry>
          <surface>
            <friction>
              <ode/>
            </friction>
            <bounce/>
            <contact/>
          </surface>
        </collision>
        <visual name='visual'>
          <geometry>
            <plane>
              <normal>0 0 1</normal>
              <size>100 100</size>
            </plane>
          </geometry>
          <material>
            <ambient>0.800000012 0.800000012 0.800000012 1</ambient>
            <diffuse>0.800000012 0.800000012 0.800000012 1</diffuse>
            <specular>0.800000012 0.800000012 0.800000012 1</specular>
          </material>
        </visual>
        <pose>0 0 0 0 0 0</pose>
        <inertial>
          <pose>0 0 0 0 0 0</pose>
          <mass>1</mass>
          <inertia>
            <ixx>1</ixx>
            <ixy>0</ixy>
            <ixz>0</ixz>
            <iyy>1</iyy>
            <iyz>0</iyz>
            <izz>1</izz>
          </inertia>
        </inertial>
        <enable_wind>false</enable_wind>
      </link>
      <pose>0 0 0 0 0 0</pose>
      <self_collide>false</self_collide>
    </model>
    <include>
      <uri>https://fuel.gazebosim.org/1.0/OpenRobotics/models/NUS_SEDS_OMNIDIRECTIONAL_GROUND_VEHICLE_VISUALS_ONLY</uri>
      <name>Ground_Robot</name>
      <pose>0 0 3 0 0 0</pose>
    </include>
    <model name='x3'>
      <frame name='_merged__x3__model__' attached_to='X3/base_link'>
        <pose relative_to='__model__'>0 0 0.053302000000000002 0 0 0</pose>
      </frame>
      <link name='X3/base_link'>
        <pose>0 0 0.053302000000000002 0 0 0</pose>
        <inertial>
          <pose>0 0 0 0 0 0</pose>
          <mass>1.5</mass>
          <inertia>
            <ixx>0.034756299999999997</ixx>
            <ixy>0</ixy>
            <ixz>0</ixz>
            <iyy>0.070000000000000007</iyy>
            <iyz>0</iyz>
            <izz>0.097699999999999995</izz>
          </inertia>
        </inertial>
        <collision name='X3/base_link_inertia_collision'>
          <pose>0 0 0 0 0 0</pose>
          <geometry>
            <box>
              <size>0.46999999999999997 0.46999999999999997 0.11</size>
            </box>
          </geometry>
          <surface>
            <friction>
              <ode/>
            </friction>
            <bounce/>
            <contact/>
          </surface>
        </collision>
        <visual name='X3/base_link_inertia_visual'>
          <pose>0 0 0 0 0 0</pose>
          <geometry>
            <mesh>
              <scale>1 1 1</scale>
              <uri>https://fuel.gazebosim.org/1.0/openrobotics/models/x3%20uav/6/files/meshes/x3.dae</uri>
            </mesh>
          </geometry>
        </visual>
        <sensor name='downward_camera' type='camera'>
          <pose>0 0 -0.20000000000000001 3.1415926535897931 1.5707926536359933 3.1415926535897931</pose>
          <topic>__default__</topic>
          <update_rate>30</update_rate>
          <enable_metrics>false</enable_metrics>
          <camera name='__default__'>
            <pose>0 0 0 0 0 0</pose>
            <horizontal_fov>1.0469999999999999</horizontal_fov>
            <image>
              <width>320</width>
              <height>240</height>
              <format>RGB_INT8</format>
              <anti_aliasing>4</anti_aliasing>
            </image>
            <camera_info_topic>__default__</camera_info_topic>
            <trigger_topic></trigger_topic>
            <triggered>false</triggered>
            <clip>
              <near>0.10000000000000001</near>
              <far>100</far>
            </clip>
            <save enabled='false'>
              <path>__default__</path>
            </save>
            <visibility_mask>4294967295</visibility_mask>
            <noise>
              <type>none</type>
              <mean>0</mean>
              <stddev>0</stddev>
            </noise>
            <distortion>
              <k1>0</k1>
              <k2>0</k2>
              <k3>0</k3>
              <p1>0</p1>
              <p2>0</p2>
              <center>0.5 0.5</center>
            </distortion>
            <lens>
              <type>stereographic</type>
              <scale_to_hfov>true</scale_to_hfov>
              <cutoff_angle>1.5707963267948966</cutoff_angle>
              <env_texture_size>256</env_texture_size>
            </lens>
            <optical_frame_id></optical_frame_id>
          </camera>
        </sensor>
        <gravity>false</gravity>
        <enable_wind>false</enable_wind>
      </link>
      <link name='X3/rotor_0'>
        <pose>0.13 -0.22 0.076302000000000092 0 0 0</pose>
        <inertial>
          <pose>0 0 0 0 0 0</pose>
          <mass>0.0050000000000000001</mass>
          <inertia>
            <ixx>9.7499999999999998e-07</ixx>
            <ixy>0</ixy>
            <ixz>0</ixz>
            <iyy>4.1704099999999999e-05</iyy>
            <iyz>0</iyz>
            <izz>4.2604100000000001e-05</izz>
          </inertia>
        </inertial>
        <collision name='X3/rotor_0_collision'>
          <pose>0 0 0 0 0 0</pose>
          <geometry>
            <cylinder>
              <length>0.0050000000000000001</length>
              <radius>0.10000000000000001</radius>
            </cylinder>
          </geometry>
          <surface>
            <contact>
              <ode/>
            </contact>
            <friction>
              <ode/>
            </friction>
            <bounce/>
          </surface>
        </collision>
        <visual name='X3/rotor_0_visual'>
          <pose>0 0 0 0 0 0</pose>
          <geometry>
            <mesh>
              <scale>0.10000000000000001 0.10000000000000001 0.10000000000000001</scale>
              <uri>https://fuel.gazebosim.org/1.0/openrobotics/models/x3%20uav/6/files/meshes/propeller_ccw.dae</uri>
            </mesh>
          </geometry>
          <material>
            <script>
              <name>Gazebo/Blue</name>
              <uri>file://media/materials/scripts/gazebo.material</uri>
            </script>
          </material>
        </visual>
        <gravity>false</gravity>
        <velocity_decay/>
        <enable_wind>false</enable_wind>
      </link>
      <joint name='X3/rotor_0_joint' type='revolute'>
        <child>X3/rotor_0</child>
        <parent>X3/base_link</parent>
        <axis>
          <xyz>0 0 1</xyz>
          <limit>
            <lower>-10000000000000000</lower>
            <upper>10000000000000000</upper>
            <effort>inf</effort>
            <velocity>inf</velocity>
            <stiffness>100000000</stiffness>
            <dissipation>1</dissipation>
          </limit>
          <dynamics>
            <spring_reference>0</spring_reference>
            <spring_stiffness>0</spring_stiffness>
            <damping>0</damping>
            <friction>0</friction>
          </dynamics>
        </axis>
        <pose>0 0 0 0 0 0</pose>
      </joint>
      <link name='X3/rotor_1'>
        <pose>-0.13 0.20000000000000001 0.076302000000000092 0 0 0</pose>
        <inertial>
          <pose>0 0 0 0 0 0</pose>
          <mass>0.0050000000000000001</mass>
          <inertia>
            <ixx>9.7499999999999998e-07</ixx>
            <ixy>0</ixy>
            <ixz>0</ixz>
            <iyy>4.1704099999999999e-05</iyy>
            <iyz>0</iyz>
            <izz>4.2604100000000001e-05</izz>
          </inertia>
        </inertial>
        <collision name='X3/rotor_1_collision'>
          <pose>0 0 0 0 0 0</pose>
          <geometry>
            <cylinder>
              <length>0.0050000000000000001</length>
              <radius>0.10000000000000001</radius>
            </cylinder>
          </geometry>
          <surface>
            <contact>
              <ode/>
            </contact>
            <friction>
              <ode/>
            </friction>
            <bounce/>
          </surface>
        </collision>
        <visual name='X3/rotor_1_visual'>
          <pose>0 0 0 0 0 0</pose>
          <geometry>
            <mesh>
              <scale>0.10000000000000001 0.10000000000000001 0.10000000000000001</scale>
              <uri>https://fuel.gazebosim.org/1.0/openrobotics/models/x3%20uav/6/files/meshes/propeller_ccw.dae</uri>
            </mesh>
          </geometry>
          <material>
            <script>
              <name>Gazebo/Red</name>
              <uri>file://media/materials/scripts/gazebo.material</uri>
            </script>
          </material>
        </visual>
        <gravity>false</gravity>
        <velocity_decay/>
        <enable_wind>false</enable_wind>
      </link>
      <joint name='X3/rotor_1_joint' type='revolute'>
        <child>X3/rotor_1</child>
        <parent>X3/base_link</parent>
        <axis>
          <xyz>0 0 1</xyz>
          <limit>
            <lower>-10000000000000000</lower>
            <upper>10000000000000000</upper>
            <effort>inf</effort>
            <velocity>inf</velocity>
            <stiffness>100000000</stiffness>
            <dissipation>1</dissipation>
          </limit>
          <dynamics>
            <spring_reference>0</spring_reference>
            <spring_stiffness>0</spring_stiffness>
            <damping>0</damping>
            <friction>0</friction>
          </dynamics>
        </axis>
        <pose>0 0 0 0 0 0</pose>
      </joint>
      <link name='X3/rotor_2'>
        <pose>0.13 0.22 0.076302000000000092 0 0 0</pose>
        <inertial>
          <pose>0 0 0 0 0 0</pose>
          <mass>0.0050000000000000001</mass>
          <inertia>
            <ixx>9.7499999999999998e-07</ixx>
            <ixy>0</ixy>
            <ixz>0</ixz>
            <iyy>4.1704099999999999e-05</iyy>
            <iyz>0</iyz>
            <izz>4.2604100000000001e-05</izz>
          </inertia>
        </inertial>
        <collision name='X3/rotor_2_collision'>
          <pose>0 0 0 0 0 0</pose>
          <geometry>
            <cylinder>
              <length>0.0050000000000000001</length>
              <radius>0.10000000000000001</radius>
            </cylinder>
          </geometry>
          <surface>
            <contact>
              <ode/>
            </contact>
            <friction>
              <ode/>
            </friction>
            <bounce/>
          </surface>
        </collision>
        <visual name='X3/rotor_2_visual'>
          <pose>0 0 0 0 0 0</pose>
          <geometry>
            <mesh>
              <scale>0.10000000000000001 0.10000000000000001 0.10000000000000001</scale>
              <uri>https://fuel.gazebosim.org/1.0/openrobotics/models/x3%20uav/6/files/meshes/propeller_cw.dae</uri>
            </mesh>
          </geometry>
          <material>
            <script>
              <name>Gazebo/Blue</name>
              <uri>file://media/materials/scripts/gazebo.material</uri>
            </script>
          </material>
        </visual>
        <gravity>false</gravity>
        <velocity_decay/>
        <enable_wind>false</enable_wind>
      </link>
      <joint name='X3/rotor_2_joint' type='revolute'>
        <child>X3/rotor_2</child>
        <parent>X3/base_link</parent>
        <axis>
          <xyz>0 0 1</xyz>
          <limit>
            <lower>-10000000000000000</lower>
            <upper>10000000000000000</upper>
            <effort>inf</effort>
            <velocity>inf</velocity>
            <stiffness>100000000</stiffness>
            <dissipation>1</dissipation>
          </limit>
          <dynamics>
            <spring_reference>0</spring_reference>
            <spring_stiffness>0</spring_stiffness>
            <damping>0</damping>
            <friction>0</friction>
          </dynamics>
        </axis>
        <pose>0 0 0 0 0 0</pose>
      </joint>
      <link name='X3/rotor_3'>
        <pose>-0.13 -0.20000000000000001 0.076302000000000092 0 0 0</pose>
        <inertial>
          <pose>0 0 0 0 0 0</pose>
          <mass>0.0050000000000000001</mass>
          <inertia>
            <ixx>9.7499999999999998e-07</ixx>
            <ixy>0</ixy>
            <ixz>0</ixz>
            <iyy>4.1704099999999999e-05</iyy>
            <iyz>0</iyz>
            <izz>4.2604100000000001e-05</izz>
          </inertia>
        </inertial>
        <collision name='X3/rotor_3_collision'>
          <pose>0 0 0 0 0 0</pose>
          <geometry>
            <cylinder>
              <length>0.0050000000000000001</length>
              <radius>0.10000000000000001</radius>
            </cylinder>
          </geometry>
          <surface>
            <contact>
              <ode/>
            </contact>
            <friction>
              <ode/>
            </friction>
            <bounce/>
          </surface>
        </collision>
        <visual name='X3/rotor_3_visual'>
          <pose>0 0 0 0 0 0</pose>
          <geometry>
            <mesh>
              <scale>0.10000000000000001 0.10000000000000001 0.10000000000000001</scale>
              <uri>https://fuel.gazebosim.org/1.0/openrobotics/models/x3%20uav/6/files/meshes/propeller_cw.dae</uri>
            </mesh>
          </geometry>
          <material>
            <script>
              <name>Gazebo/Red</name>
              <uri>file://media/materials/scripts/gazebo.material</uri>
            </script>
          </material>
        </visual>
        <gravity>false</gravity>
        <velocity_decay/>
        <enable_wind>false</enable_wind>
      </link>
      <joint name='X3/rotor_3_joint' type='revolute'>
        <child>X3/rotor_3</child>
        <parent>X3/base_link</parent>
        <axis>
          <xyz>0 0 1</xyz>
          <limit>
            <lower>-10000000000000000</lower>
            <upper>10000000000000000</upper>
            <effort>inf</effort>
            <velocity>inf</velocity>
            <stiffness>100000000</stiffness>
            <dissipation>1</dissipation>
          </limit>
          <dynamics>
            <spring_reference>0</spring_reference>
            <spring_stiffness>0</spring_stiffness>
            <damping>0</damping>
            <friction>0</friction>
          </dynamics>
        </axis>
        <pose>0 0 0 0 0 0</pose>
      </joint>
      <plugin name='gz::sim::systems::PosePublisher' filename='gz-sim-pose-publisher-system'>
        <publish_link_pose>true</publish_link_pose>
      </plugin>
      <plugin name='gz::sim::systems::OdometryPublisher' filename='gz-sim-odometry-publisher-system'>
        <odom_frame>x3/odom</odom_frame>
        <robot_base_frame>x3</robot_base_frame>
      </plugin>
      <plugin name='gz::sim::systems::VelocityControl' filename='gz-sim-velocity-control-system'>
        <model_name>x3</model_name>
        <topic>/model/x3/cmd_vel</topic>
      </plugin>
      <pose>0 0 10 0 0 0</pose>
      <static>false</static>
      <self_collide>false</self_collide>
    </model>
    <model name='terrain'>
      <frame name='_merged__terrain_1__model__' attached_to='body'>
        <pose relative_to='__model__'>0 0 0 0 0 0</pose>
      </frame>
      <link name='body'>
        <visual name='visual'>
          <geometry>
            <mesh>
              <uri>file:///home/cirl/ros_gz_project_template-main/install/ros_gz_example_gazebo/share/ros_gz_example_gazebo/worlds/media/terrain_1.dae</uri>
            </mesh>
          </geometry>
          <material>
            <ambient>1 1 1 1</ambient>
            <diffuse>1 1 1 1</diffuse>
            <specular>0.100000001 0.100000001 0.100000001 1</specular>
            <pbr>
              <metal>
                <albedo_map>./media/Textures/Grass.png</albedo_map>
              </metal>
            </pbr>
          </material>
        </visual>
        <collision name='collision'>
          <geometry>
            <mesh>
              <uri>file:///home/cirl/ros_gz_project_template-main/install/ros_gz_example_gazebo/share/ros_gz_example_gazebo/worlds/media/terrain_1.dae</uri>
            </mesh>
          </geometry>
        </collision>
        <pose>0 0 0 0 0 0</pose>
        <inertial>
          <pose>0 0 0 0 0 0</pose>
          <mass>1</mass>
          <inertia>
            <ixx>1</ixx>
            <ixy>0</ixy>
            <ixz>0</ixz>
            <iyy>1</iyy>
            <iyz>0</iyz>
            <izz>1</izz>
          </inertia>
        </inertial>
        <enable_wind>false</enable_wind>
      </link>
      <pose>0 0 2 0 0 0</pose>
      <static>false</static>
      <self_collide>false</self_collide>
    </model>
    <include>
      <uri>https://fuel.gazebosim.org/1.0/OpenRobotics/models/Pine Tree</uri>
      <name>Tree1</name>
      <pose>0 10 1.3779200315475464 0 0 0</pose>
    </include>
    <include>
      <uri>https://fuel.gazebosim.org/1.0/OpenRobotics/models/Pine Tree</uri>
      <name>Tree2</name>
      <pose>0 -10 1.085604190826416 0 0 0</pose>
    </include>
    <include>
      <uri>https://fuel.gazebosim.org/1.0/OpenRobotics/models/Pine Tree</uri>
      <name>Tree1_1</name>
      <pose>-3.2139595004580261 12.231658686887073 1.3779200315475464 0 0 0</pose>
    </include>
    <include>
      <uri>https://fuel.gazebosim.org/1.0/OpenRobotics/models/Pine Tree</uri>
      <name>Tree1_2</name>
      <pose>-3.2504948869614214 9.3292281216305941 1.3779200315475464 0 0 0</pose>
    </include>
    <include>
      <uri>https://fuel.gazebosim.org/1.0/OpenRobotics/models/Pine Tree</uri>
      <name>Tree1_3</name>
      <pose>-6.7633888221783316 12.885799452192028 1.3779200315475464 0 0 0</pose>
    </include>
    <include>
      <uri>https://fuel.gazebosim.org/1.0/OpenRobotics/models/Pine Tree</uri>
      <name>Tree1_4</name>
      <pose>-5.9903904920482507 10.403570548343071 1.3779200315475464 0 0 0</pose>
    </include>
    <include>
      <uri>https://fuel.gazebosim.org/1.0/OpenRobotics/models/Pine Tree</uri>
      <name>Tree1_5</name>
      <pose>-8.4815676323814806 8.4013526890981272 1.3779200315475464 0 0 0</pose>
    </include>
    <include>
      <uri>https://fuel.gazebosim.org/1.0/OpenRobotics/models/Pine Tree</uri>
      <name>Tree1_6</name>
      <pose>-10.337459265888485 14.41495271404235 1.3779200315475464 0 0 0</pose>
    </include>
    <include>
      <uri>https://fuel.gazebosim.org/1.0/OpenRobotics/models/Pine Tree</uri>
      <name>Tree1_7</name>
      <pose>-10.074536500900827 11.332467986034544 1.3779200315475464 0 0 0</pose>
    </include>
    <include>
      <uri>https://fuel.gazebosim.org/1.0/OpenRobotics/models/Pine Tree</uri>
      <name>Tree1_8</name>
      <pose>-13.843413831958106 13.196529147689315 1.3779200315475464 0 0 0</pose>
    </include>
    <include>
      <uri>https://fuel.gazebosim.org/1.0/OpenRobotics/models/Pine Tree</uri>
      <name>Tree1_9</name>
      <pose>-11.712993823721062 9.1068496561785608 1.3779200315475464 0 0 0</pose>
    </include>
    <include>
      <uri>https://fuel.gazebosim.org/1.0/OpenRobotics/models/Pine Tree</uri>
      <name>Tree1_10</name>
      <pose>-13.957376398162012 6.1132454185368861 1.3779200315475464 0 0 0</pose>
    </include>
    <include>
      <uri>https://fuel.gazebosim.org/1.0/OpenRobotics/models/Pine Tree</uri>
      <name>Tree1_11</name>
      <pose>-3.3847408608765619 -8.223898564622738 1.3779200315475464 0 0 0</pose>
    </include>
    <include>
      <uri>https://fuel.gazebosim.org/1.0/OpenRobotics/models/Pine Tree</uri>
      <name>Tree1_12</name>
      <pose>-1.9482319924276759 -12.804297775200419 1.3779200315475464 0 0 0</pose>
    </include>
    <include>
      <uri>https://fuel.gazebosim.org/1.0/OpenRobotics/models/Pine Tree</uri>
      <name>Tree1_13</name>
      <pose>2.7381467544533358 -13.254793627210727 1.3779200315475464 0 0 0</pose>
    </include>
    <include>
      <uri>https://fuel.gazebosim.org/1.0/OpenRobotics/models/Pine Tree</uri>
      <name>Tree1_14</name>
      <pose>-6.5138606447374041 -14.232319953425709 1.3779200315475464 0 0 0</pose>
    </include>
    <include>
      <uri>https://fuel.gazebosim.org/1.0/OpenRobotics/models/Pine Tree</uri>
      <name>Tree1_15</name>
      <pose>-6.4534241497448761 -11.028314996993702 1.3779200315475464 0 0 0</pose>
    </include>
    <include>
      <uri>https://fuel.gazebosim.org/1.0/OpenRobotics/models/Pine Tree</uri>
      <name>Tree1_16</name>
      <pose>-9.0027703540136574 -8.1708297038645235 1.3779200315475464 0 0 0</pose>
    </include>
    <include>
      <uri>https://fuel.gazebosim.org/1.0/OpenRobotics/models/Pine Tree</uri>
      <name>Tree1_17</name>
      <pose>-10.715981004935008 -11.034381349350644 1.3779200315475464 0 0 0</pose>
    </include>
    <include>
      <uri>https://fuel.gazebosim.org/1.0/OpenRobotics/models/Pine Tree</uri>
      <name>Tree1_18</name>
      <pose>-11.657373258424062 -14.6842496703959 1.3779200315475464 0 0 0</pose>
    </include>
    <include>
      <uri>https://fuel.gazebosim.org/1.0/OpenRobotics/models/Pine Tree</uri>
      <name>Tree1_19</name>
      <pose>-13.682590859303874 -9.171552778880578 1.3779200315475464 0 0 0</pose>
    </include>
    <include>
      <uri>https://fuel.gazebosim.org/1.0/OpenRobotics/models/Pine Tree</uri>
      <name>Tree1_20</name>
      <pose>7.2340835608942733 -12.32434190291616 1.3779200315475464 0 0 0</pose>
    </include>
    <include>
      <uri>https://fuel.gazebosim.org/1.0/OpenRobotics/models/Pine Tree</uri>
      <name>Tree1_21</name>
      <pose>11.963776778930646 -11.198281412650477 1.3779200315475464 0 0 0</pose>
    </include>
    <include>
      <uri>https://fuel.gazebosim.org/1.0/OpenRobotics/models/Pine Tree</uri>
      <name>Tree1_22</name>
      <pose>6.0393177549496997 -8.5385968142252882 1.3779200315475464 0 0 0</pose>
    </include>
    <include>
      <uri>https://fuel.gazebosim.org/1.0/OpenRobotics/models/Pine Tree</uri>
      <name>Tree1_23</name>
      <pose>11.582539366893396 -6.3077492078992865 1.3779200315475464 0 0 0</pose>
    </include>
    <include>
      <uri>https://fuel.gazebosim.org/1.0/OpenRobotics/models/Pine Tree</uri>
      <name>Tree1_24</name>
      <pose>10.647793979722245 7.4410795638027771 1.3779200315475464 0 0 0</pose>
    </include>
    <include>
      <uri>https://fuel.gazebosim.org/1.0/OpenRobotics/models/Pine Tree</uri>
      <name>Tree1_25</name>
      <pose>11.879600505163221 12.426364698268502 1.3779200315475464 0 0 0</pose>
    </include>
    <include>
      <uri>https://fuel.gazebosim.org/1.0/OpenRobotics/models/Pine Tree</uri>
      <name>Tree1_26</name>
      <pose>6.1811544842263224 9.1337534825340612 1.3779200315475464 0 0 0</pose>
    </include>
    <include>
      <uri>https://fuel.gazebosim.org/1.0/OpenRobotics/models/Pine Tree</uri>
      <name>Tree1_27</name>
      <pose>3.1180084026085062 12.717874704628221 1.3779200315475464 0 0 0</pose>
    </include>
    <include>
      <uri>https://fuel.gazebosim.org/1.0/OpenRobotics/models/Pine Tree</uri>
      <name>Tree1_28</name>
      <pose>7.1409825220366869 12.762762740929462 1.3779200315475464 0 0 0</pose>
    </include>
    <light name='sun' type='directional'>
      <pose>0 0 10 0 0 0</pose>
      <cast_shadows>true</cast_shadows>
      <intensity>1</intensity>
      <direction>-0.5 0.10000000000000001 -0.90000000000000002</direction>
      <diffuse>0.800000012 0.800000012 0.800000012 1</diffuse>
      <specular>0.200000003 0.200000003 0.200000003 1</specular>
      <attenuation>
        <range>1000</range>
        <linear>0.01</linear>
        <constant>0.90000000000000002</constant>
        <quadratic>0.001</quadratic>
      </attenuation>
      <spot>
        <inner_angle>0</inner_angle>
        <outer_angle>0</outer_angle>
        <falloff>0</falloff>
      </spot>
    </light>
  </world>
</sdf>
